Workbook

Sheet Data Entry
B2: STUDENT DATA COLLECTION
B3: Total Students Entered: | C3: =COUNTA(B6:B300) -> 140 | D3: Total Fee Balance: | E3: =SUM(E6:E300) -> 25930
B5: Adm No | C5: Student Name | D5: Grade | E5: Fee Balance | F5: Parent Name | G5: Parent Phone No
B6: {=IF(C6:C300<>"",ROW(C6:C300)+94,"")} -> 100 | C6: Cleons Klein | D6: Playgroup | E6: 700
B7: 101 | C7: Jayden Makworo | D7: Playgroup | E7: Cleared
B8: 102 | C8: Shirleen Nyatero | D8: Playgroup | E8: Cleared
B9: 103 | C9: Eddah Moraa | D9: Playgroup | E9: Cleared
B10: 104 | C10: Anita Osoro | D10: Playgroup | E10: Cleared
B11: 105 | C11: Victor Monari | D11: Playgroup | E11: Cleared
B12: 106 | C12: Merrane Kwamboka | D12: Playgroup | E12: Cleared | F12: John Chweya | G12: 0726690763
B13: 107 | C13: Giannah Moraa | D13: Playgroup | E13: KES 1,000.00 | F13: Evans Nyamweya | G13: 0796929168
B14: 108 | C14: Fabian Mochoni | D14: Playgroup | E14: Cleared
B15: 109 | C15: Emmanuel Braxley | D15: Playgroup | E15: 900
B16: 110 | C16: Jayden Obegi | D16: Playgroup | E16: KES 1,400.00
B17: 111 | C17: Leon Mose | D17: Playgroup | E17: KES 1,000.00
B18: 112 | C18: Blessings Nyabate | D18: Playgroup | E18: 600
B19: 113 | C19: Holy Bless Lucky | D19: Playgroup | E19: Cleared | F19: Justus Mageto | G19: 0711959810
B20: 114 | C20: Georges Ongera | D20: Playgroup | E20: Cleared
B21: 115 | C21: Emmanuel Nyonkangi | D21: Playgroup | E21: 500 | F21: Peter Nyokangi | G21: 0714082361
B22: 116 | C22: Melvin Nyantika | D22: Playgroup | E22: 500 | F22: Atika Mageto | G22: 0742785135
B23: 117 | C23: Lucas Nyabuto | D23: Playgroup | E23: KES 1,100.00 | F23: Vincent Akunga | G23: 0798982805
B24: 118 | C24: Grayson Thomas | D24: Playgroup | E24: Cleared
B25: 119 | C25: Ezekiel Ongodi | D25: Playgroup | E25: Cleared
B26: 120 | C26: Tiffan Kerubo | D26: Playgroup | E26: KES 2,200.00
B27: 121 | C27: Allen Alloys | D27: Playgroup | E27: KES 3,200.00 | F27: Ann Kerubo | G27: 0700537100
B28: 122 | C28: Precious Bosibori | D28: Playgroup | E28: Cleared
B29: 123 | C29: Magdaline Zakayo | D29: Playgroup | E29: Cleared | F29: Zakayo Anyango | G29: 0721289001
B30: 124 | C30: Titus Ochara | D30: Playgroup | E30: 350
B31: 125 | C31: Ian Makana | D31: Playgroup | E31: KES 2,800.00
B32: 126 | C32: Austine Orioki | D32: PP1 | E32: Cleared
B33: 127 | C33: Jayden Angwenyi | D33: PP1 | E33: KES 2,800.00
B34: 128 | C34: Shem Nyanamba | D34: PP1 | E34: Cleared
B35: 129 | C35: Perpetua Kerubo | D35: PP1 | E35: 550
B36: 130 | C36: Wendy Favour | D36: PP1 | E36: KES 2,900.00
B37: 131 | C37: Rachael Anthony | D37: PP1 | E37: Cleared
B38: 132 | C38: Ruthmyrrh Gichana | D38: PP1 | E38: Cleared | F38: Roseline Kerubo | G38: 0717907751
B39: 133 | C39: Fred Geofilla | D39: PP1 | E39: 500
B40: 134 | C40: Shirleen Ong'ondi | D40: PP1 | E40: 500
B41: 135 | C41: Precious Kerubo | D41: PP1 | E41: 200
B42: 136 | C42: Griffins Matara | D42: PP1 | E42: Cleared
...

Sheet Grade Summary
B2: GRADE SUMMARY
B4: Grade | C4: Total Students | D4: Total Fee Balance
B5: Playgroup | C5: =COUNTIF('Data Entry'!D:D,B5) -> 26 | D5: =SUMIF('Data Entry'!D:D,B5,'Data Entry'!E:E) -> 3550
B6: PP1 | C6: =COUNTIF('Data Entry'!D:D,B6) -> 40 | D6: =SUMIF('Data Entry'!D:D,B6,'Data Entry'!E:E) -> 4630
B7: PP2 | C7: =COUNTIF('Data Entry'!D:D,B7) -> 35 | D7: =SUMIF('Data Entry'!D:D,B7,'Data Entry'!E:E) -> 3800
B8: Grade 1 | C8: =COUNTIF('Data Entry'!D:D,B8) -> 32 | D8: =SUMIF('Data Entry'!D:D,B8,'Data Entry'!E:E) -> 3550
B9: Grade 2 | C9: =COUNTIF('Data Entry'!D:D,B9) -> 24 | D9: =SUMIF('Data Entry'!D:D,B9,'Data Entry'!E:E) -> 6100
B10: Grade 3 | C10: =COUNTIF('Data Entry'!D:D,B10) -> 29 | D10: =SUMIF('Data Entry'!D:D,B10,'Data Entry'!E:E) -> 1800
B11: Grade 4 | C11: =COUNTIF('Data Entry'!D:D,B11) -> 28 | D11: =SUMIF('Data Entry'!D:D,B11,'Data Entry'!E:E) -> 1250
B12: Grade 5 | C12: =COUNTIF('Data Entry'!D:D,B12) -> 27 | D12: =SUMIF('Data Entry'!D:D,B12,'Data Entry'!E:E) -> 400
B13: Grade 6 | C13: =COUNTIF('Data Entry'!D:D,B13) -> 20 | D13: =SUMIF('Data Entry'!D:D,B13,'Data Entry'!E:E) -> 850
B14: Grade 7 | C14: =COUNTIF('Data Entry'!D:D,B14) -> 9 | D14: =SUMIF('Data Entry'!D:D,B14,'Data Entry'!E:E) -> 0
B15: Grade 8 | C15: =COUNTIF('Data Entry'!D:D,B15) -> 13 | D15: =SUMIF('Data Entry'!D:D,B15,'Data Entry'!E:E) -> 0
B16: Grade 9 | C16: =COUNTIF('Data Entry'!D:D,B16) -> 12 | D16: =SUMIF('Data Entry'!D:D,B16,'Data Entry'!E:E) -> 0

Sheet Staff Directory
B2: STAFF DATA COLLECTION
B3: Total Staff Entered: | C3: =COUNTA(B6:B105) -> 20
B5: No. | C5: Staff ID | D5: Full Name | E5: Gender | F5: Phone | G5: Position | H5: Subject/Department | I5: Employment Type | J5: Date Joined | K5: Status | L5: Salary
B6: 1 | C6: 12460817 | D6: Daniel Odongo | F6: 0726904117 | G6: Administrator | L6: 12000
B7: 2 | C7: 8130256 | D7: Robert Mogere | F7: 0725925268 | G7: Administrator | L7: 9500
B8: 3 | C8: — | D8: Amos Siro Onsongo | F8: 0117587544 | G8: Teacher | L8: 7500
B9: 4 | C9: 36882511 | D9: Gordon Odiwuor | F9: 0720207597 | G9: Teacher | L9: 7500
B10: 5 | C10: 38871014 | D10: Lillian Otieno | F10: 0757542843 | G10: Teacher | L10: 7500
B11: 6 | C11: 40036701 | D11: Patricia Kusamboka | F11: 0706185422 | G11: Teacher | L11: 7500
B12: 7 | C12: 40068298 | D12: Sheilla Bosibori | F12: 0793016108 | G12: Teacher | L12: 7500
B13: 8 | C13: 41145875 | D13: Alfine Otieno | F13: 0117766761 | G13: Teacher | L13: 6500
B14: 9 | C14: 36602106 | D14: Agostine Ogega | F14: 0700419964 | G14: Teacher | L14: 7500
B15: 10 | C15: — | D15: Morghan Amecha | F15: 0798838358 | G15: Teacher | L15: 7500
B16: 11 | C16: — | D16: Winnie Bosibori | F16: 0111693700 | G16: Teacher | L16: 6500
B17: 12 | C17: — | D17: Joshua Ngara | F17: 0740550392 | G17: Teacher | L17: 6500
B18: 13 | C18: — | D18: Josephine Otaro | F18: 0701135478 | G18: Teacher | L18: 7500
B19: 14 | C19: — | D19: Doreen Bosibori | F19: — | G19: Teacher | L19: 6500
B20: 15 | C20: — | D20: Cecillia Kemunto | F20: 0757655224 | G20: Teacher | L20: 6000
B21: 16 | C21: — | D21: Leonidah Kigwaro | F21: — | G21: Support Staff | L21: 6000
B22: 17 | C22: 3976544 | D22: Nicodemus Achuka | F22: 0769779634 | G22: Support Staff | L22: 6500
B23: 18 | C23: — | D23: Grace Jefta | F23: 0752808415 | G23: Support Staff | L23: 6000
B24: 19 | C24: — | D24: Jane Moraa | F24: 0710944832 | G24: Support Staff | L24: 4500
B25: 20 | C25: — | D25: Jefta Makori | F25: — | G25: Support Staff | L25: 4500
D26: Marcela Osoro

Sheet Inventory Tracker
B2: SCHOOL INVENTORY COLLECTION
B3: Total Items: | C3: =COUNTA(B6:B205) -> 0 | D3: Total Value: | E3: =SUM(G6:G205) -> 0
B5: Item ID | C5: Item Name | D5: Category | E5: Quantity | F5: Unit Price | G5: Total Value | H5: Condition
G6: {=IF(ISNUMBER(E6:E205)*ISNUMBER(F6:F205),E6:E205*F6:F205,"")}

Sheet Fee Structure
B2: KABIERO ACADEMY — FEE STRUCTURE 2026
B4: Applicable To | C4: Fee Description | D4: Term 1 | E4: Term 2 | F4: Term 3 | G4: Total
B5: PP1 / PP2 / Grade 1 / Grade 2 | C5: School Fees | D5: KES 3,800.00 | E5: KES 2,800.00 | F5: KES 1,800.00 | G5: KES 8,400.00
B6: Grade 1–6 | C6: School Fees | D6: KES 4,800.00 | E6: KES 3,800.00 | F6: KES 1,800.00 | G6: KES 10,400.00
B7: Grade 7, 8 & 9 | C7: School Fees | D7: KES 5,500.00 | E7: KES 4,500.00 | F7: KES 2,500.00 | G7: KES 12,500.00
B8: All Students | C8: Parental Award | D8: 300 | E8: 300 | F8: 300 | G8: 900
B9: All Students | C9: Medical | D9: 100 | E9: 100 | F9: 100 | G9: 300
B10: Grade 1 onwards | C10: Activity | D10: 200 | E10: 200 | F10: 0 | G10: 400
B11: All Students (Optional) | C11: Lunch | D11: KES 3,000.00 | E11: KES 3,000.00 | F11: KES 3,000.00 | G11: KES 9,000.00
